Workbook
Name _\a: #REF!
Name _\b: #REF!
Name _\c: #REF!
Name _\d: #REF!
Name _\g: #REF!
Name _\p: #REF!
Name _\r: #REF!
Name _\t: #REF!
Name _\x: #REF!
Name __\a: #REF!
Name __\b: #REF!
Name __\c: #REF!
Name __\d: #REF!
Name __\g: #REF!
Name __\p: #REF!
Name __\r: #REF!
Name __\t: #REF!
Name __\x: #REF!
Name ___\a: #REF!
Name ___\b: #REF!
Name ___\c: #REF!
Name ___\d: #REF!
Name ___\g: #REF!
Name ___\p: #REF!
Name ___\r: #REF!
Name ___\t: #REF!
Name ___\x: #REF!
Name AwalES: #REF!
Name AwalES: #REF!
Name AwalES: #REF!
Name CACCORD: #REF!
Name CACCORD: #REF!
Name CACCORD: #REF!
Name CBENZ: #REF!
Name CBENZ: #REF!
Name CBENZ: #REF!
Name CBMW_520: #REF!
Name CBMW_520: #REF!
Name CBMW_520: #REF!
Name CCAKRA: #REF!
Name CCAKRA: #REF!
Name CCAKRA: #REF!
Name CCEFIRO: #REF!
Name CCEFIRO: #REF!
Name CCEFIRO: #REF!
Name CCHARADE: #REF!
Name CCHARADE: #REF!
Name CCHARADE: #REF!
Name CCITY: #REF!
Name CCITY: #REF!
Name CCITY: #REF!
Name CCIVIC: #REF!
Name CCIVIC: #REF!
Name CCIVIC: #REF!
Name CCOROLLA: #REF!
Name CCOROLLA: #REF!
Name CCOROLLA: #REF!
Name CCORONA: #REF!
Name CCORONA: #REF!
Name CCORONA: #REF!

Sheet How To
B5: 1. | C5: Update data yang ada di sheet "OS" yang di kolom KUNING SECARA 5 HARIAN, yang tidak berwarna kuning jangan di otak-atik
C7: Dealer | D7: Outlet Code (Sales Code) | E7: Outlet Name | F7: Katashiki | G7: Suffix | H7: Tanggal SPK | I7: Status SPK | J7: Status Supply | K7: Tanggal Cut Of
I8: FIRMED | J8: MATCH MDP
I9: PENDING LOAN | J9: MATCH SUPPLY STOCK ON HAND
I10: ALREADY DO | J10: UNMATCH
I11: CANCEL
I12: CUSTOMER PENDING ISSUE
B14: 2.
F17: Update tanggal cut off tiap 5 HARIAN
B22: 3. | C22: Setelah semua data sudah diinput dengan benar, silahkan masuk ke sheet "Pvt OS" -> klik 1x di pivot table manapun -> pilih di menu bar "Analyze" -> pilih "Refresh All"
B23: 4. | C23: Masuk ke sheet "AO Report" -> input angka OP Target pada kolom yang tersedia
B33: 5. | C33: Masuk ke sheet "Action Plan" -> input angka Stock, MDP, dan Carry Over unit pada tabel yang tersedia
B50: 6. | C50: Input plan DO from OS Matching per 5 harian dengan mempertimbangkan jumlah Stock On Hand dan MDP heijunka
B66: 7. | C66: Masuk ke sheet "Reason Unmatch" -> update kolom yang ada dengan angka yang ada pada pivot di sebelah kanan -> jelaskan pula reason pada kolom "Remarks"
B83: 8. | C83: Masuk ke sheet "Action Plan" -> update kolom yang ada dengan angka yang ada pada pivot di sebelah kanan -> jelaskan pula reason pada kolom "Action Plan to Sell"

Sheet AO Report(0)
O1: ''
B2: AREA OPERATION REPORT - TUNAS NATIONAL - as of | R2: =OS!A6 -> 46244
C4: [A] Stock Matching with OS | AD4: Closing Estimation | AM4: RSSP OM | AP4: 0.85
G6: =SUM(G7:G21) -> 53 | AD6: OAP Target | AE6: 92 | AM6: OPT | AN6: 87 | AP6: =AE6-AE7 -> 39
C7: =AE10-X22 -> 123 | E7: =C7 -> 123 | G7: =GETPIVOTDATA("Area AGM",'Pvt OS'!$AG$8) -> 1 | N7: MATCHING RATIO | Q7: =O14/G6 -> 0.79245283 | AD7: [A] Matching with Outstanding | AE7: =SUM(X16:X22) -> 53 | AF7: =AE7/AE9 -> 0.57608696 | AM7: EC | AN7: 2185
C8: =C7-C19 -> 81 | E8: =C8 -> 81 | H8: =GETPIVOTDATA("Area AGM",'Pvt OS'!$AK$8) -> 0 | AD8: [B] New Order (SPK) | AE8: =X58 -> 39 | AF8: =AE8/$AE$9 -> 0.42391304 | AM8: Gap | AN8: =AN7-AE7 -> 2132
G9: =GETPIVOTDATA("Area AGM",'Pvt OS'!$Y$8) -> 4 | J9: =GETPIVOTDATA("Area AGM",'Pvt OS'!$BI$8) -> 5 | X9: =AE6 -> 92 | AD9: Total Estimasi Closing [A+B] | AE9: =AE7+AE8 -> 92 | AF9: =AE9/AE6 -> 1 | AN9: 2185
H10: =GETPIVOTDATA("Area AGM",'Pvt OS'!$AC$8) -> 0 | J10: =SUM(H9:H10) -> 0 | X10: =X9-SUM(X16:X22) -> 39 | AD10: Total Invoicable Stock | AE10: ='Action Plan'!F27 -> 133 | AN10: =AN9-AE9 -> 2093
G11: =GETPIVOTDATA("Area AGM",'Pvt OS'!$Q$8) -> 0 | J11: =SUM(K11:K14) -> 7 | K11: =GETPIVOTDATA("Area AGM",'Pvt OS'!$BE$8) -> 0 | AD11: Efficiency (STO) | AE11: =AE9/AE10 -> 0.69172932 | AM11: =2125-AE7 -> 2072 | AN11: =AM11/2125 -> 0.97505882
H12: =GETPIVOTDATA("Area AGM",'Pvt OS'!$U$8) -> 0
G13: =GETPIVOTDATA("Area AGM",'Pvt OS'!$I$8) -> 0 | K13: =GETPIVOTDATA("Area AGM",'Pvt OS'!$BA$8) -> 0
H14: =GETPIVOTDATA("Area AGM",'Pvt OS'!$M$8) -> 0 | K14: =GETPIVOTDATA("Area AGM",'Pvt OS'!$AW$8) -> 7 | O14: =SUM(O15:O20) -> 42 | U14: Total potential DO fr OS : | V14: =SUM(X16:X22) -> 53
G15: =SUM(H15:H20) -> 48 | H15: =GETPIVOTDATA("Area AGM",'Pvt OS'!$E$8) -> 18 | J15: =SUM(K15:K21) -> 42 | K15: =H12+H14 -> 0 | O15: =J15-O19 -> 26 | X15: =X16-O14 -> 1 | AM15: =88%*AE6 -> 80.96 | AN15: 1960
K16: =GETPIVOTDATA("Area AGM",'Pvt OS'!$AS$8) -> 18 | V16: =ROUND($O$14*V$78,0) -> 13 | X16: =SUM(Q21,R20,S19,T18,U17,V16) -> 43 | AN16: =AN15-AE6 -> 1868 | AP16: =X22+O14 -> 52
U17: =ROUND($O$14*U$78,0) -> 11 | AP17: 1800
T18: =ROUND($O$14*T$78,0) -> 10 | AP18: =AP17-AP16 -> 1748
C19: =J15 -> 42 | E19: =C19 -> 42 | H19: =GETPIVOTDATA("Area AGM",'Pvt OS'!$A$8) -> 30 | K19: =GETPIVOTDATA("Area AGM",'Pvt OS'!$AO$8) -> 24 | O19: =IFERROR(GETPIVOTDATA("Area AGM",'Pvt OS'!$BM$8,"Status Supply","Match Supply Stock On Hand"),0)+IFERROR(GETPIVOTDATA("Area AGM",'Pvt OS'!$BP$8,"Status Supply","Match Supply Stock On Hand"),0) -> 16 | S19: =ROUND($O$14*S$78,0) -> 9
R20: =ROUND($O$14*R$78,0) -> 0 | S20: s
Q21: =ROUND($O$14*Q$78,0) -> 0
G22: ,, | Q22: 3 | R22: 7 | X22: =SUM(Q22:V22) -> 10 | Y22: MTD
C23: Full Stock | E23: Invoicable Stk | G23: OS Order | J23: Stock Matching | Q23: 1-5 | R23: 6-10 | S23: 11-15 | T23: 16-20 | U23: 21-25 | V23: 25-31
O25: Revised Plan
O26: Original Plan
O27: Actual RS
S34: 0.4 | T34: 0.6 | V34: =3948-AE7-#REF! -> #REF!
C35: [B] Matching Stock from Order
AR36: SPK Nett actual
C37: SPK plan | AR37: GAP
F38: 1-5 | G38: 6-10 | H38: 11-15 | I38: 16-20 | J38: 21-25 | K38: 25-31 | X38: =X39+X44 -> 114
E39: TTL | F39: Effective to N RS | J39: For N+1 RS | V39: =K50 -> 19 | X39: =V39+U42 -> 38 | Z39: N+1 OP tgt | AA39: Day 21-30 CKD SPK | AB39: Comp.
C40: SPK Gross Plan | E40: 122 | F40: =SUM(F41:I41) -> 80 | J40: =SUM(J41:K41) -> 42
F41: =F82 -> 20 | G41: 20 | H41: 20 | I41: =I82 -> 20 | J41: 20 | K41: 22
C42: SPK Gross actual | E42: =SUM(F42:K42) -> 54 | F42: 30 | G42: 24 | U42: =J50 -> 19 | Z42: 1727 | AA42: =X39 -> 38 | AB42: =AA42/Z42 -> 0.022003474
C43: GAP | F43: =F42-F41 -> 10 | G43: =G42-G41 -> 4 | H43: =H42-H41 -> -20 | I43: =I42-I41 -> -20 | J43: =J42-J41 -> -20 | K43: =K42-K41 -> -22
T44: =I50 -> 19 | X44: =SUM(Q51,R48,S46,T44) -> 76
C45: Cancellation assum. | E45: =SUM(F45:K45) -> 6 | F45: =ROUND($M$47*F41,0) -> 1 | G45: =ROUND($M$47*G41,0) -> 1 | H45: =ROUND($M$47*H41,0) -> 1 | I45: =ROUND($M$47*I41,0) -> 1 | J45: =ROUND($M$47*J41,0) -> 1 | K45: =ROUND($M$47*K41,0) -> 1 | M45: Cancel ratio
C46: Cancellation actual | E46: =SUM(F46:K46) -> 0 | F46: 0 | G46: 0 | H46: 0 | I46: 0 | J46: 0 | M46: 3m avg. | N46: Loan rej. | S46: =H50 -> 19
C47: Cancellation ratio | F47: =IFERROR(F46/F42,0) -> 0 | G47: =IFERROR(G46/G42,0) -> 0 | H47: =IFERROR(H46/H42,0) -> 0 | I47: =IFERROR(I46/I42,0) -> 0 | J47: =IFERROR(J46/J42,0) -> 0 | K47: =IFERROR(K46/K42,0) -> 0 | M47: 0.04 | N47: 0.02
R48: =G50 -> 19
C49: SPK Nett Plan | E49: =SUM(F50:K50) -> 114 | F49: =SUM(F50:I50) -> 76 | J49: =SUM(J50:K50) -> 38
...

Sheet Remaining Target
C5: DO AFI | D5: 1-5 | E5: 6-10 | F5: 11-15 | G5: 16-20 | H5: 21-25 | I5: 26-EOM
C6: Ori Plan
C7: Revised Plan
C8: Actual DO
C9: GAP | D9: =D8-D6 -> 0 | E9: =E8-E6 -> 0 | F9: =F8-F6 -> 0 | G9: =G8-G6 -> 0 | H9: =H8-H6 -> 0 | I9: =I7-I6 -> 0

Sheet by MDL
D2: 1 Minggu | E2: 2 Minggu | F2: 3 Minggu | G2: 4 Minggu | H2: > 4 Minggu | J2: All | K2: <30D
B3: Status OS yg sudah matching tapi diestimasikan tetap tidak bisa jadi RS di bulan ini
B4: Gap from OS | C4: Matched Unfirmed (PL + CPI) | I4: Unmatched to Stock
D6: 1 w | E6: 2 w | F6: 3 w | G6: 4 w | H6: >4 w | J6: Firmed | K6: P.Loan | L6: Remarks
B7: Avanza New | C7: =SUM(D7:G7) -> 0 | D7: =IFERROR(GETPIVOTDATA("Area AGM",#REF!,"Dealer",""&$S$18&"","Model",""&$B7&"","Umur Outstansing",""&D$2&""),0) -> 0 | E7: =IFERROR(GETPIVOTDATA("Area AGM",#REF!,"Dealer",""&$S$18&"","Model",""&$B7&"","Umur Outstansing",""&E$2&""),0) -> 0 | F7: =IFERROR(GETPIVOTDATA("Area AGM",#REF!,"Dealer",""&$S$18&"","Model",""&$B7&"","Umur Outstansing",""&F$2&""),0) -> 0 | G7: =IFERROR(GETPIVOTDATA("Area AGM",#REF!,"Dealer",""&$S$18&"","Model",""&$B7&"","Umur Outstansing",""&G$2&""),0) -> 0 | H7: =IFERROR(GETPIVOTDATA("Area AGM",#REF!,"Dealer",""&$S$18&"","Model",""&$B7&"","Umur Outstansing",""&H$2&""),0) -> 0 | I7: =SUM(J7:K7) -> 0 | J7: =IFERROR(GETPIVOTDATA("Area AGM",#REF!,"Dealer",""&$S$18&"","Model",""&$B7&""),0) -> 0 | K7: =IFERROR(GETPIVOTDATA("Area AGM",#REF!,"Dealer",""&$S$18&"","Model",""&$B7&""),0) -> 0 | L7: - Maximize swapping & change facility - Re-offer with the current type & color available | P7: Budi Jaya
B8: Veloz New | C8: =SUM(D8:G8) -> 0 | D8: =IFERROR(GETPIVOTDATA("Area AGM",#REF!,"Dealer",""&$S$18&"","Model",""&$B8&"","Umur Outstansing",""&D$2&""),0) -> 0 | E8: =IFERROR(GETPIVOTDATA("Area AGM",#REF!,"Dealer",""&$S$18&"","Model",""&$B8&"","Umur Outstansing",""&E$2&""),0) -> 0 | F8: =IFERROR(GETPIVOTDATA("Area AGM",#REF!,"Dealer",""&$S$18&"","Model",""&$B8&"","Umur Outstansing",""&F$2&""),0) -> 0 | G8: =IFERROR(GETPIVOTDATA("Area AGM",#REF!,"Dealer",""&$S$18&"","Model",""&$B8&"","Umur Outstansing",""&G$2&""),0) -> 0 | H8: =IFERROR(GETPIVOTDATA("Area AGM",#REF!,"Dealer",""&$S$18&"","Model",""&$B8&"","Umur Outstansing",""&H$2&""),0) -> 0 | I8: =SUM(J8:K8) -> 0 | J8: =IFERROR(GETPIVOTDATA("Area AGM",#REF!,"Dealer",""&$S$18&"","Model",""&$B8&""),0) -> 0 | K8: =IFERROR(GETPIVOTDATA("Area AGM",#REF!,"Dealer",""&$S$18&"","Model",""&$B8&""),0) -> 0 | P8: Duta Cendana
B9: Raize | C9: =SUM(D9:G9) -> 0 | D9: =IFERROR(GETPIVOTDATA("Area AGM",#REF!,"Dealer",""&$S$18&"","Model",""&$B9&"","Umur Outstansing",""&D$2&""),0) -> 0 | E9: =IFERROR(GETPIVOTDATA("Area AGM",#REF!,"Dealer",""&$S$18&"","Model",""&$B9&"","Umur Outstansing",""&E$2&""),0) -> 0 | F9: =IFERROR(GETPIVOTDATA("Area AGM",#REF!,"Dealer",""&$S$18&"","Model",""&$B9&"","Umur Outstansing",""&F$2&""),0) -> 0 | G9: =IFERROR(GETPIVOTDATA("Area AGM",#REF!,"Dealer",""&$S$18&"","Model",""&$B9&"","Umur Outstansing",""&G$2&""),0) -> 0 | H9: =IFERROR(GETPIVOTDATA("Area AGM",#REF!,"Dealer",""&$S$18&"","Model",""&$B9&"","Umur Outstansing",""&H$2&""),0) -> 0 | I9: =SUM(J9:K9) -> 0 | J9: =IFERROR(GETPIVOTDATA("Area AGM",#REF!,"Dealer",""&$S$18&"","Model",""&$B9&""),0) -> 0 | K9: =IFERROR(GETPIVOTDATA("Area AGM",#REF!,"Dealer",""&$S$18&"","Model",""&$B9&""),0) -> 0 | P9: Selamat Toyota
B10: Agya | C10: =SUM(D10:G10) -> 0 | D10: =IFERROR(GETPIVOTDATA("Area AGM",#REF!,"Dealer",""&$S$18&"","Model",""&$B10&"","Umur Outstansing",""&D$2&""),0) -> 0 | E10: =IFERROR(GETPIVOTDATA("Area AGM",#REF!,"Dealer",""&$S$18&"","Model",""&$B10&"","Umur Outstansing",""&E$2&""),0) -> 0 | F10: =IFERROR(GETPIVOTDATA("Area AGM",#REF!,"Dealer",""&$S$18&"","Model",""&$B10&"","Umur Outstansing",""&F$2&""),0) -> 0 | G10: =IFERROR(GETPIVOTDATA("Area AGM",#REF!,"Dealer",""&$S$18&"","Model",""&$B10&"","Umur Outstansing",""&G$2&""),0) -> 0 | H10: =IFERROR(GETPIVOTDATA("Area AGM",#REF!,"Dealer",""&$S$18&"","Model",""&$B10&"","Umur Outstansing",""&H$2&""),0) -> 0 | I10: =SUM(J10:K10) -> 0 | J10: =IFERROR(GETPIVOTDATA("Area AGM",#REF!,"Dealer",""&$S$18&"","Model",""&$B10&""),0) -> 0 | K10: =IFERROR(GETPIVOTDATA("Area AGM",#REF!,"Dealer",""&$S$18&"","Model",""&$B10&""),0) -> 0 | P10: Sinar Mas
B11: Calya | C11: =SUM(D11:G11) -> 0 | D11: =IFERROR(GETPIVOTDATA("Area AGM",#REF!,"Dealer",""&$S$18&"","Model",""&$B11&"","Umur Outstansing",""&D$2&""),0) -> 0 | E11: =IFERROR(GETPIVOTDATA("Area AGM",#REF!,"Dealer",""&$S$18&"","Model",""&$B11&"","Umur Outstansing",""&E$2&""),0) -> 0 | F11: =IFERROR(GETPIVOTDATA("Area AGM",#REF!,"Dealer",""&$S$18&"","Model",""&$B11&"","Umur Outstansing",""&F$2&""),0) -> 0 | G11: =IFERROR(GETPIVOTDATA("Area AGM",#REF!,"Dealer",""&$S$18&"","Model",""&$B11&"","Umur Outstansing",""&G$2&""),0) -> 0 | H11: =IFERROR(GETPIVOTDATA("Area AGM",#REF!,"Dealer",""&$S$18&"","Model",""&$B11&"","Umur Outstansing",""&H$2&""),0) -> 0 | I11: =SUM(J11:K11) -> 0 | J11: =IFERROR(GETPIVOTDATA("Area AGM",#REF!,"Dealer",""&$S$18&"","Model",""&$B11&""),0) -> 0 | K11: =IFERROR(GETPIVOTDATA("Area AGM",#REF!,"Dealer",""&$S$18&"","Model",""&$B11&""),0) -> 0 | P11: Rejeki Toyota
B12: Yaris | C12: =SUM(D12:G12) -> 0 | D12: =IFERROR(GETPIVOTDATA("Area AGM",#REF!,"Dealer",""&$S$18&"","Model",""&$B12&"","Umur Outstansing",""&D$2&""),0) -> 0 | E12: =IFERROR(GETPIVOTDATA("Area AGM",#REF!,"Dealer",""&$S$18&"","Model",""&$B12&"","Umur Outstansing",""&E$2&""),0) -> 0 | F12: =IFERROR(GETPIVOTDATA("Area AGM",#REF!,"Dealer",""&$S$18&"","Model",""&$B12&"","Umur Outstansing",""&F$2&""),0) -> 0 | G12: =IFERROR(GETPIVOTDATA("Area AGM",#REF!,"Dealer",""&$S$18&"","Model",""&$B12&"","Umur Outstansing",""&G$2&""),0) -> 0 | H12: =IFERROR(GETPIVOTDATA("Area AGM",#REF!,"Dealer",""&$S$18&"","Model",""&$B12&"","Umur Outstansing",""&H$2&""),0) -> 0 | I12: =SUM(J12:K12) -> 0 | J12: =IFERROR(GETPIVOTDATA("Area AGM",#REF!,"Dealer",""&$S$18&"","Model",""&$B12&""),0) -> 0 | K12: =IFERROR(GETPIVOTDATA("Area AGM",#REF!,"Dealer",""&$S$18&"","Model",""&$B12&""),0) -> 0 | P12: Astrido Toyota
B13: Innova | C13: =SUM(D13:G13) -> 0 | D13: =IFERROR(GETPIVOTDATA("Area AGM",#REF!,"Dealer",""&$S$18&"","Model",""&$B13&"","Umur Outstansing",""&D$2&""),0) -> 0 | E13: =IFERROR(GETPIVOTDATA("Area AGM",#REF!,"Dealer",""&$S$18&"","Model",""&$B13&"","Umur Outstansing",""&E$2&""),0) -> 0 | F13: =IFERROR(GETPIVOTDATA("Area AGM",#REF!,"Dealer",""&$S$18&"","Model",""&$B13&"","Umur Outstansing",""&F$2&""),0) -> 0 | G13: =IFERROR(GETPIVOTDATA("Area AGM",#REF!,"Dealer",""&$S$18&"","Model",""&$B13&"","Umur Outstansing",""&G$2&""),0) -> 0 | H13: =IFERROR(GETPIVOTDATA("Area AGM",#REF!,"Dealer",""&$S$18&"","Model",""&$B13&"","Umur Outstansing",""&H$2&""),0) -> 0 | I13: =SUM(J13:K13) -> 0 | J13: =IFERROR(GETPIVOTDATA("Area AGM",#REF!,"Dealer",""&$S$18&"","Model",""&$B13&""),0) -> 0 | K13: =IFERROR(GETPIVOTDATA("Area AGM",#REF!,"Dealer",""&$S$18&"","Model",""&$B13&""),0) -> 0 | P13: Auto2000
B14: Fortuner 4x2 | C14: =SUM(D14:G14) -> 0 | D14: =IFERROR(GETPIVOTDATA("Area AGM",#REF!,"Dealer",""&$S$18&"","Model",""&$B14&"","Umur Outstansing",""&D$2&""),0) -> 0 | E14: =IFERROR(GETPIVOTDATA("Area AGM",#REF!,"Dealer",""&$S$18&"","Model",""&$B14&"","Umur Outstansing",""&E$2&""),0) -> 0 | F14: =IFERROR(GETPIVOTDATA("Area AGM",#REF!,"Dealer",""&$S$18&"","Model",""&$B14&"","Umur Outstansing",""&F$2&""),0) -> 0 | G14: =IFERROR(GETPIVOTDATA("Area AGM",#REF!,"Dealer",""&$S$18&"","Model",""&$B14&"","Umur Outstansing",""&G$2&""),0) -> 0 | H14: =IFERROR(GETPIVOTDATA("Area AGM",#REF!,"Dealer",""&$S$18&"","Model",""&$B14&"","Umur Outstansing",""&H$2&""),0) -> 0 | I14: =SUM(J14:K14) -> 0 | J14: =IFERROR(GETPIVOTDATA("Area AGM",#REF!,"Dealer",""&$S$18&"","Model",""&$B14&""),0) -> 0 | K14: =IFERROR(GETPIVOTDATA("Area AGM",#REF!,"Dealer",""&$S$18&"","Model",""&$B14&""),0) -> 0 | P14: Merdeka Motor
B15: Rush | C15: =SUM(D15:G15) -> 0 | D15: =IFERROR(GETPIVOTDATA("Area AGM",#REF!,"Dealer",""&$S$18&"","Model",""&$B15&"","Umur Outstansing",""&D$2&""),0) -> 0 | E15: =IFERROR(GETPIVOTDATA("Area AGM",#REF!,"Dealer",""&$S$18&"","Model",""&$B15&"","Umur Outstansing",""&E$2&""),0) -> 0 | F15: =IFERROR(GETPIVOTDATA("Area AGM",#REF!,"Dealer",""&$S$18&"","Model",""&$B15&"","Umur Outstansing",""&F$2&""),0) -> 0 | G15: =IFERROR(GETPIVOTDATA("Area AGM",#REF!,"Dealer",""&$S$18&"","Model",""&$B15&"","Umur Outstansing",""&G$2&""),0) -> 0 | H15: =IFERROR(GETPIVOTDATA("Area AGM",#REF!,"Dealer",""&$S$18&"","Model",""&$B15&"","Umur Outstansing",""&H$2&""),0) -> 0 | I15: =SUM(J15:K15) -> 0 | J15: =IFERROR(GETPIVOTDATA("Area AGM",#REF!,"Dealer",""&$S$18&"","Model",""&$B15&""),0) -> 0 | K15: =IFERROR(GETPIVOTDATA("Area AGM",#REF!,"Dealer",""&$S$18&"","Model",""&$B15&""),0) -> 0 | P15: Plaza Toyota
B16: Others | C16: =SUM(D16:G16) -> 0 | D16: =SUM(D21:D53) -> 0 | E16: =SUM(E21:E53) -> 0 | F16: =SUM(F21:F53) -> 0 | G16: =SUM(G21:G53) -> 0 | H16: =SUM(H21:H52) -> 0 | I16: =SUM(J16:K16) -> 0 | J16: =SUM(J21:J53) -> 0 | K16: =SUM(K21:K53) -> 0 | P16: Wijaya Toyota
B17: Grand Total | C17: =SUM(D17:G17) -> 0 | D17: =SUM(D7:D16) -> 0 | E17: =SUM(E7:E16) -> 0 | F17: =SUM(F7:F16) -> 0 | G17: =SUM(G7:G16) -> 0 | H17: =SUM(H7:H16) -> 0 | I17: =SUM(I7:I16) -> 0 | J17: =SUM(J7:J16) -> 0 | K17: =SUM(K7:K16) -> 0 | P17: Tunas Toyota
S18: Duta Cendana
S19: Model | T19: Stock Matching | U19: Unfirmed & Match | V19: BU | W19: Total OS | X19: OS Match | Y19: Firmed & Match >60D | Z19: Firmed & Match 30-60D | AA19: Firmed & Match <30D | AB19: PL Match <30D | AC19: Stock EOM | AD19: Distplan | AE19: MDP TLS | AF19: C/O | AG19: 2nd Allo | AH19: Delay | AI19: Total Supply | AJ19: RS Latest | AK19: Remaining FFS | AL19: Gap fr Matching | AM19: FFS | AN19: C/O AFI | AO19: C/O AFI not yet DO | AP19: SPK Latest | AQ19: RS from new SPK | AR19: Remaining SPK | AU19: Action Plan to Sell | BA19: Funnel Plan
Q20: STO | R20: OP | AL20: Gap fr Matching | AS20: Match fr New SPK | AT20: Un Match | BA20: Leads/Prospect | BB20: Hot Prospect | BC20: SPK | BD20: DO
B21: ALPHARD | C21: =SUM(D21:G21) -> 0 | D21: =IFERROR(GETPIVOTDATA("Area AGM",#REF!,"Dealer",""&$S$18&"","Model",""&$B21&"","Umur Outstansing",""&D$2&""),0) -> 0 | E21: =IFERROR(GETPIVOTDATA("Area AGM",#REF!,"Dealer",""&$S$18&"","Model",""&$B21&"","Umur Outstansing",""&E$2&""),0) -> 0 | F21: =IFERROR(GETPIVOTDATA("Area AGM",#REF!,"Dealer",""&$S$18&"","Model",""&$B21&"","Umur Outstansing",""&F$2&""),0) -> 0 | G21: =IFERROR(GETPIVOTDATA("Area AGM",#REF!,"Dealer",""&$S$18&"","Model",""&$B21&"","Umur Outstansing",""&G$2&""),0) -> 0 | H21: =IFERROR(GETPIVOTDATA("Area AGM",#REF!,"Dealer",""&$S$18&"","Model",""&$B21&"","Umur Outstansing",""&H$2&""),0) -> 0 | J21: =IFERROR(GETPIVOTDATA("Area AGM",#REF!,"Dealer",""&$S$18&"","Model",""&$B21&""),0) -> 0 | K21: =IFERROR(GETPIVOTDATA("Area AGM",#REF!,"Dealer",""&$S$18&"","Model",""&$B21&""),0) -> 0 | P21: Avanza New | Q21: =IFERROR(R21/AI21,0) -> 0 | R21: =IFERROR(GETPIVOTDATA("RS Target",#REF!,"Dealer",""&$S$18&"","Model",""&$P21&""),0) -> 0 | S21: Avanza New | T21: =SUM(Y21:AB21,AO21) -> 0 | U21: =IFERROR(GETPIVOTDATA("Area AGM",'Pvt OS'!#REF!,"Dealer",""&$S$18&"","Model",""&$S21&""),0) -> 0 | V21: =W21-X21 -> 0 | W21: =IFERROR(GETPIVOTDATA("Area AGM",'Pvt OS'!#REF!,"Dealer",""&$S$18&"","Model",""&$S21&""),0)+IFERROR(GETPIVOTDATA("Area AGM",'Pvt OS'!$A$8,"Dealer",""&$S$18&"","Model",""&$S21&""),0) -> 0 | X21: =SUM(Y21:AB21) -> 0 | Y21: =IFERROR(GETPIVOTDATA("Area AGM",'Pvt OS'!$U$8,"Dealer",""&$S$18&"","Model",""&$S21&""),0) -> 0 | Z21: =IFERROR(GETPIVOTDATA("Area AGM",'Pvt OS'!$M$8,"Dealer",""&$S$18&"","Model",""&$S21&""),0) -> 0 | AA21: =IFERROR(GETPIVOTDATA("Area AGM",'Pvt OS'!#REF!,"Dealer",""&$S$18&"","Model",""&$S21&""),0) -> 0 | AB21: =IFERROR(GETPIVOTDATA("Area AGM",'Pvt OS'!$AO$8,"Dealer",""&$S$18&"","Model",""&$S21&""),0) -> 0 | AC21: =IFERROR(GETPIVOTDATA("Stock",#REF!,"Dealer",""&$S$18&"","Model",""&$S21&""),0) -> 0 | AD21: =IFERROR(GETPIVOTDATA("MDP",#REF!,"Dealer",""&$S$18&"","Model",""&$S21&""),0) -> 0 | AE21: =IFERROR(GETPIVOTDATA("RRN",#REF!,"Model2",""&$S21&"","Dealer",""&$S$18&""),0) -> 0 | AF21: =IFERROR(GETPIVOTDATA("CO",#REF!,"Dealer Name",""&$S$18&"","Model",""&$S21&""),0) -> 0 | AG21: =IFERROR(GETPIVOTDATA("Sum of Distplan Final",#REF!,"Dealer",""&$S$18&"","Model",""&$S21&""),0) -> 0 | AH21: =IFERROR(GETPIVOTDATA("RRN",#REF!,"Model",""&$S21&"","Dealer",""&$S$18&""),0) -> 0 | AI21: =AC21+AD21+AF21+AG21-AH21 -> 0 | AJ21: =IFERROR(GETPIVOTDATA("volume_rs",#REF!,"Model",""&$S21&"","Dealer",""&$S$18&""),0) -> 0 | AK21: =AI21-AJ21-X21+AN21 -> 0 | AL21: =IFERROR(GETPIVOTDATA("Area AGM",'Pvt OS'!#REF!,"Dealer",""&$S$18&"","Model",""&$S21&""),0) -> 0 | AM21: =AK21+AL21 -> 0 | AN21: =IFERROR(GETPIVOTDATA("Row Labels",#REF!,"Dealer",""&$S$18&"","Model",""&$S21&""),0) -> 0 | AO21: =IFERROR(GETPIVOTDATA("RS Afi",#REF!,"Dealer",""&$S$18&"","Model",""&$S21&""),0) -> 0 | AP21: =IFERROR(GETPIVOTDATA("qty",#REF!,"Model",""&$S21&"","Dealer",""&$S$18&""),0) -> 0 | AQ21: =IFERROR(GETPIVOTDATA("volume_rs",#REF!,"Model",""&$S21&"","Dealer",""&$S$18&""),0) -> 0 | AR21: =AP21-AQ21 -> 0 | AS21: =IFERROR(GETPIVOTDATA("Area AGM",'Pvt OS'!#REF!,"Dealer",""&$S$18&"","Model",""&$S21&""),0) -> 0 | AT21: =AR21-AS21 -> 0 | AU21: Attached | BA21: =#REF! -> #REF! | BB21: =#REF! -> #REF! | BC21: =#REF! -> #REF! | BD21: =#REF! -> #REF!
B22: AVANZA | C22: =SUM(D22:G22) -> 0 | D22: =IFERROR(GETPIVOTDATA("Area AGM",#REF!,"Dealer",""&$S$18&"","Model",""&$B22&"","Umur Outstansing",""&D$2&""),0) -> 0 | E22: =IFERROR(GETPIVOTDATA("Area AGM",#REF!,"Dealer",""&$S$18&"","Model",""&$B22&"","Umur Outstansing",""&E$2&""),0) -> 0 | F22: =IFERROR(GETPIVOTDATA("Area AGM",#REF!,"Dealer",""&$S$18&"","Model",""&$B22&"","Umur Outstansing",""&F$2&""),0) -> 0 | G22: =IFERROR(GETPIVOTDATA("Area AGM",#REF!,"Dealer",""&$S$18&"","Model",""&$B22&"","Umur Outstansing",""&G$2&""),0) -> 0 | H22: =IFERROR(GETPIVOTDATA("Area AGM",#REF!,"Dealer",""&$S$18&"","Model",""&$B22&"","Umur Outstansing",""&H$2&""),0) -> 0 | J22: =IFERROR(GETPIVOTDATA("Area AGM",#REF!,"Dealer",""&$S$18&"","Model",""&$B22&""),0) -> 0 | K22: =IFERROR(GETPIVOTDATA("Area AGM",#REF!,"Dealer",""&$S$18&"","Model",""&$B22&""),0) -> 0 | P22: Veloz New | Q22: =IFERROR(R22/AI22,0) -> 0 | R22: =IFERROR(GETPIVOTDATA("RS Target",#REF!,"Dealer",""&$S$18&"","Model",""&$P22&""),0) -> 0 | S22: Veloz New | T22: =SUM(Y22:AB22,AO22) -> 0 | U22: =IFERROR(GETPIVOTDATA("Area AGM",'Pvt OS'!#REF!,"Dealer",""&$S$18&"","Model",""&$S22&""),0) -> 0 | V22: =W22-X22 -> 0 | W22: =IFERROR(GETPIVOTDATA("Area AGM",'Pvt OS'!#REF!,"Dealer",""&$S$18&"","Model",""&$S22&""),0)+IFERROR(GETPIVOTDATA("Area AGM",'Pvt OS'!$A$8,"Dealer",""&$S$18&"","Model",""&$S22&""),0) -> 0 | X22: =SUM(Y22:AB22) -> 0 | Y22: =IFERROR(GETPIVOTDATA("Area AGM",'Pvt OS'!$U$8,"Dealer",""&$S$18&"","Model",""&$S22&""),0) -> 0 | Z22: =IFERROR(GETPIVOTDATA("Area AGM",'Pvt OS'!$M$8,"Dealer",""&$S$18&"","Model",""&$S22&""),0) -> 0 | AA22: =IFERROR(GETPIVOTDATA("Area AGM",'Pvt OS'!#REF!,"Dealer",""&$S$18&"","Model",""&$S22&""),0) -> 0 | AB22: =IFERROR(GETPIVOTDATA("Area AGM",'Pvt OS'!$AO$8,"Dealer",""&$S$18&"","Model",""&$S22&""),0) -> 0 | AC22: =IFERROR(GETPIVOTDATA("Stock",#REF!,"Dealer",""&$S$18&"","Model",""&$S22&""),0) -> 0 | AD22: =IFERROR(GETPIVOTDATA("MDP",#REF!,"Dealer",""&$S$18&"","Model",""&$S22&""),0) -> 0 | AE22: =IFERROR(GETPIVOTDATA("RRN",#REF!,"Model2",""&$S22&"","Dealer",""&$S$18&""),0) -> 0 | AF22: =IFERROR(GETPIVOTDATA("CO",#REF!,"Dealer Name",""&$S$18&"","Model",""&$S22&""),0) -> 0 | AG22: =IFERROR(GETPIVOTDATA("Sum of Distplan Final",#REF!,"Dealer",""&$S$18&"","Model",""&$S22&""),0) -> 0 | AH22: =IFERROR(GETPIVOTDATA("RRN",#REF!,"Model",""&$S22&"","Dealer",""&$S$18&""),0) -> 0 | AI22: =AC22+AD22+AF22+AG22-AH22 -> 0 | AJ22: =IFERROR(GETPIVOTDATA("volume_rs",#REF!,"Model",""&$S22&"","Dealer",""&$S$18&""),0) -> 0 | AK22: =AI22-AJ22-X22+AN22 -> 0 | AL22: =IFERROR(GETPIVOTDATA("Area AGM",'Pvt OS'!#REF!,"Dealer",""&$S$18&"","Model",""&$S22&""),0) -> 0 | AM22: =AK22+AL22 -> 0 | AN22: =IFERROR(GETPIVOTDATA("Row Labels",#REF!,"Dealer",""&$S$18&"","Model",""&$S22&""),0) -> 0 | AO22: =IFERROR(GETPIVOTDATA("RS Afi",#REF!,"Dealer",""&$S$18&"","Model",""&$S22&""),0) -> 0 | AP22: =IFERROR(GETPIVOTDATA("qty",#REF!,"Model",""&$S22&"","Dealer",""&$S$18&""),0) -> 0 | AQ22: =IFERROR(GETPIVOTDATA("volume_rs",#REF!,"Model",""&$S22&"","Dealer",""&$S$18&""),0) -> 0 | AR22: =AP22-AQ22 -> 0 | AS22: =IFERROR(GETPIVOTDATA("Area AGM",'Pvt OS'!#REF!,"Dealer",""&$S$18&"","Model",""&$S22&""),0) -> 0 | AT22: =AR22-AS22 -> 0 | BA22: =#REF! -> #REF! | BB22: =#REF! -> #REF! | BC22: =#REF! -> #REF! | BD22: =#REF! -> #REF!
B23: SIENTA | C23: =SUM(D23:G23) -> 0 | D23: =IFERROR(GETPIVOTDATA("Area AGM",#REF!,"Dealer",""&$S$18&"","Model",""&$B23&"","Umur Outstansing",""&D$2&""),0) -> 0 | E23: =IFERROR(GETPIVOTDATA("Area AGM",#REF!,"Dealer",""&$S$18&"","Model",""&$B23&"","Umur Outstansing",""&E$2&""),0) -> 0 | F23: =IFERROR(GETPIVOTDATA("Area AGM",#REF!,"Dealer",""&$S$18&"","Model",""&$B23&"","Umur Outstansing",""&F$2&""),0) -> 0 | G23: =IFERROR(GETPIVOTDATA("Area AGM",#REF!,"Dealer",""&$S$18&"","Model",""&$B23&"","Umur Outstansing",""&G$2&""),0) -> 0 | H23: =IFERROR(GETPIVOTDATA("Area AGM",#REF!,"Dealer",""&$S$18&"","Model",""&$B23&"","Umur Outstansing",""&H$2&""),0) -> 0 | J23: =IFERROR(GETPIVOTDATA("Area AGM",#REF!,"Dealer",""&$S$18&"","Model",""&$B23&""),0) -> 0 | K23: =IFERROR(GETPIVOTDATA("Area AGM",#REF!,"Dealer",""&$S$18&"","Model",""&$B23&""),0) -> 0 | P23: Raize | Q23: =IFERROR(R23/AI23,0) -> 0 | R23: =IFERROR(GETPIVOTDATA("RS Target",#REF!,"Dealer",""&$S$18&"","Model",""&$P23&""),0) -> 0 | S23: Raize | T23: =SUM(Y23:AB23,AO23) -> 0 | U23: =IFERROR(GETPIVOTDATA("Area AGM",'Pvt OS'!#REF!,"Dealer",""&$S$18&"","Model",""&$S23&""),0) -> 0 | V23: =W23-X23 -> 0 | W23: =IFERROR(GETPIVOTDATA("Area AGM",'Pvt OS'!#REF!,"Dealer",""&$S$18&"","Model",""&$S23&""),0)+IFERROR(GETPIVOTDATA("Area AGM",'Pvt OS'!$A$8,"Dealer",""&$S$18&"","Model",""&$S23&""),0) -> 0 | X23: =SUM(Y23:AB23) -> 0 | Y23: =IFERROR(GETPIVOTDATA("Area AGM",'Pvt OS'!$U$8,"Dealer",""&$S$18&"","Model",""&$S23&""),0) -> 0 | Z23: =IFERROR(GETPIVOTDATA("Area AGM",'Pvt OS'!$M$8,"Dealer",""&$S$18&"","Model",""&$S23&""),0) -> 0 | AA23: =IFERROR(GETPIVOTDATA("Area AGM",'Pvt OS'!#REF!,"Dealer",""&$S$18&"","Model",""&$S23&""),0) -> 0 | AB23: =IFERROR(GETPIVOTDATA("Area AGM",'Pvt OS'!$AO$8,"Dealer",""&$S$18&"","Model",""&$S23&""),0) -> 0 | AC23: =IFERROR(GETPIVOTDATA("Stock",#REF!,"Dealer",""&$S$18&"","Model",""&$S23&""),0) -> 0 | AD23: =IFERROR(GETPIVOTDATA("MDP",#REF!,"Dealer",""&$S$18&"","Model",""&$S23&""),0) -> 0 | AE23: =IFERROR(GETPIVOTDATA("RRN",#REF!,"Model2",""&$S23&"","Dealer",""&$S$18&""),0) -> 0 | AF23: =IFERROR(GETPIVOTDATA("CO",#REF!,"Dealer Name",""&$S$18&"","Model",""&$S23&""),0) -> 0 | AG23: =IFERROR(GETPIVOTDATA("Sum of Distplan Final",#REF!,"Dealer",""&$S$18&"","Model",""&$S23&""),0) -> 0 | AH23: =IFERROR(GETPIVOTDATA("RRN",#REF!,"Model",""&$S23&"","Dealer",""&$S$18&""),0) -> 0 | AI23: =AC23+AD23+AF23+AG23-AH23 -> 0 | AJ23: =IFERROR(GETPIVOTDATA("volume_rs",#REF!,"Model",""&$S23&"","Dealer",""&$S$18&""),0) -> 0 | AK23: =AI23-AJ23-X23+AN23 -> 0 | AL23: =IFERROR(GETPIVOTDATA("Area AGM",'Pvt OS'!#REF!,"Dealer",""&$S$18&"","Model",""&$S23&""),0) -> 0 | AM23: =AK23+AL23 -> 0 | AN23: =IFERROR(GETPIVOTDATA("Row Labels",#REF!,"Dealer",""&$S$18&"","Model",""&$S23&""),0) -> 0 | AO23: =IFERROR(GETPIVOTDATA("RS Afi",#REF!,"Dealer",""&$S$18&"","Model",""&$S23&""),0) -> 0 | AP23: =IFERROR(GETPIVOTDATA("qty",#REF!,"Model",""&$S23&"","Dealer",""&$S$18&""),0) -> 0 | AQ23: =IFERROR(GETPIVOTDATA("volume_rs",#REF!,"Model",""&$S23&"","Dealer",""&$S$18&""),0) -> 0 | AR23: =AP23-AQ23 -> 0 | AS23: =IFERROR(GETPIVOTDATA("Area AGM",'Pvt OS'!#REF!,"Dealer",""&$S$18&"","Model",""&$S23&""),0) -> 0 | AT23: =AR23-AS23 -> 0 | BA23: =#REF! -> #REF! | BB23: =#REF! -> #REF! | BC23: =#REF! -> #REF! | BD23: =#REF! -> #REF!
B24: C-HR | C24: =SUM(D24:G24) -> 0 | D24: =IFERROR(GETPIVOTDATA("Area AGM",#REF!,"Dealer",""&$S$18&"","Model",""&$B24&"","Umur Outstansing",""&D$2&""),0) -> 0 | E24: =IFERROR(GETPIVOTDATA("Area AGM",#REF!,"Dealer",""&$S$18&"","Model",""&$B24&"","Umur Outstansing",""&E$2&""),0) -> 0 | F24: =IFERROR(GETPIVOTDATA("Area AGM",#REF!,"Dealer",""&$S$18&"","Model",""&$B24&"","Umur Outstansing",""&F$2&""),0) -> 0 | G24: =IFERROR(GETPIVOTDATA("Area AGM",#REF!,"Dealer",""&$S$18&"","Model",""&$B24&"","Umur Outstansing",""&G$2&""),0) -> 0 | H24: =IFERROR(GETPIVOTDATA("Area AGM",#REF!,"Dealer",""&$S$18&"","Model",""&$B24&"","Umur Outstansing",""&H$2&""),0) -> 0 | J24: =IFERROR(GETPIVOTDATA("Area AGM",#REF!,"Dealer",""&$S$18&"","Model",""&$B24&""),0) -> 0 | K24: =IFERROR(GETPIVOTDATA("Area AGM",#REF!,"Dealer",""&$S$18&"","Model",""&$B24&""),0) -> 0 | P24: Agya | Q24: =IFERROR(R24/AI24,0) -> 0 | R24: =IFERROR(GETPIVOTDATA("RS Target",#REF!,"Dealer",""&$S$18&"","Model",""&$P24&""),0) -> 0 | S24: Agya | T24: =SUM(Y24:AB24,AO24) -> 0 | U24: =IFERROR(GETPIVOTDATA("Area AGM",'Pvt OS'!#REF!,"Dealer",""&$S$18&"","Model",""&$S24&""),0) -> 0 | V24: =W24-X24 -> 0 | W24: =IFERROR(GETPIVOTDATA("Area AGM",'Pvt OS'!#REF!,"Dealer",""&$S$18&"","Model",""&$S24&""),0)+IFERROR(GETPIVOTDATA("Area AGM",'Pvt OS'!$A$8,"Dealer",""&$S$18&"","Model",""&$S24&""),0) -> 0 | X24: =SUM(Y24:AB24) -> 0 | Y24: =IFERROR(GETPIVOTDATA("Area AGM",'Pvt OS'!$U$8,"Dealer",""&$S$18&"","Model",""&$S24&""),0) -> 0 | Z24: =IFERROR(GETPIVOTDATA("Area AGM",'Pvt OS'!$M$8,"Dealer",""&$S$18&"","Model",""&$S24&""),0) -> 0 | AA24: =IFERROR(GETPIVOTDATA("Area AGM",'Pvt OS'!#REF!,"Dealer",""&$S$18&"","Model",""&$S24&""),0) -> 0 | AB24: =IFERROR(GETPIVOTDATA("Area AGM",'Pvt OS'!$AO$8,"Dealer",""&$S$18&"","Model",""&$S24&""),0) -> 0 | AC24: =IFERROR(GETPIVOTDATA("Stock",#REF!,"Dealer",""&$S$18&"","Model",""&$S24&""),0) -> 0 | AD24: =IFERROR(GETPIVOTDATA("MDP",#REF!,"Dealer",""&$S$18&"","Model",""&$S24&""),0) -> 0 | AE24: =IFERROR(GETPIVOTDATA("RRN",#REF!,"Model2",""&$S24&"","Dealer",""&$S$18&""),0) -> 0 | AF24: =IFERROR(GETPIVOTDATA("CO",#REF!,"Dealer Name",""&$S$18&"","Model",""&$S24&""),0) -> 0 | AG24: =IFERROR(GETPIVOTDATA("Sum of Distplan Final",#REF!,"Dealer",""&$S$18&"","Model",""&$S24&""),0) -> 0 | AH24: =IFERROR(GETPIVOTDATA("RRN",#REF!,"Model",""&$S24&"","Dealer",""&$S$18&""),0) -> 0 | AI24: =AC24+AD24+AF24+AG24-AH24 -> 0 | AJ24: =IFERROR(GETPIVOTDATA("volume_rs",#REF!,"Model",""&$S24&"","Dealer",""&$S$18&""),0) -> 0 | AK24: =AI24-AJ24-X24+AN24 -> 0 | AL24: =IFERROR(GETPIVOTDATA("Area AGM",'Pvt OS'!#REF!,"Dealer",""&$S$18&"","Model",""&$S24&""),0) -> 0 | AM24: =AK24+AL24 -> 0 | AN24: =IFERROR(GETPIVOTDATA("Row Labels",#REF!,"Dealer",""&$S$18&"","Model",""&$S24&""),0) -> 0 | AO24: =IFERROR(GETPIVOTDATA("RS Afi",#REF!,"Dealer",""&$S$18&"","Model",""&$S24&""),0) -> 0 | AP24: =IFERROR(GETPIVOTDATA("qty",#REF!,"Model",""&$S24&"","Dealer",""&$S$18&""),0) -> 0 | AQ24: =IFERROR(GETPIVOTDATA("volume_rs",#REF!,"Model",""&$S24&"","Dealer",""&$S$18&""),0) -> 0 | AR24: =AP24-AQ24 -> 0 | AS24: =IFERROR(GETPIVOTDATA("Area AGM",'Pvt OS'!#REF!,"Dealer",""&$S$18&"","Model",""&$S24&""),0) -> 0 | AT24: =AR24-AS24 -> 0 | BA24: =#REF! -> #REF! | BB24: =#REF! -> #REF! | BC24: =#REF! -> #REF! | BD24: =#REF! -> #REF!
B25: C-HR HYBRID | C25: =SUM(D25:G25) -> 0 | D25: =IFERROR(GETPIVOTDATA("Area AGM",#REF!,"Dealer",""&$S$18&"","Model",""&$B25&"","Umur Outstansing",""&D$2&""),0) -> 0 | E25: =IFERROR(GETPIVOTDATA("Area AGM",#REF!,"Dealer",""&$S$18&"","Model",""&$B25&"","Umur Outstansing",""&E$2&""),0) -> 0 | F25: =IFERROR(GETPIVOTDATA("Area AGM",#REF!,"Dealer",""&$S$18&"","Model",""&$B25&"","Umur Outstansing",""&F$2&""),0) -> 0 | G25: =IFERROR(GETPIVOTDATA("Area AGM",#REF!,"Dealer",""&$S$18&"","Model",""&$B25&"","Umur Outstansing",""&G$2&""),0) -> 0 | H25: =IFERROR(GETPIVOTDATA("Area AGM",#REF!,"Dealer",""&$S$18&"","Model",""&$B25&"","Umur Outstansing",""&H$2&""),0) -> 0 | J25: =IFERROR(GETPIVOTDATA("Area AGM",#REF!,"Dealer",""&$S$18&"","Model",""&$B25&""),0) -> 0 | K25: =IFERROR(GETPIVOTDATA("Area AGM",#REF!,"Dealer",""&$S$18&"","Model",""&$B25&""),0) -> 0 | P25: Calya | Q25: =IFERROR(R25/AI25,0) -> 0 | R25: =IFERROR(GETPIVOTDATA("RS Target",#REF!,"Dealer",""&$S$18&"","Model",""&$P25&""),0) -> 0 | S25: Calya | T25: =SUM(Y25:AB25,AO25) -> 0 | U25: =IFERROR(GETPIVOTDATA("Area AGM",'Pvt OS'!#REF!,"Dealer",""&$S$18&"","Model",""&$S25&""),0) -> 0 | V25: =W25-X25 -> 0 | W25: =IFERROR(GETPIVOTDATA("Area AGM",'Pvt OS'!#REF!,"Dealer",""&$S$18&"","Model",""&$S25&""),0)+IFERROR(GETPIVOTDATA("Area AGM",'Pvt OS'!$A$8,"Dealer",""&$S$18&"","Model",""&$S25&""),0) -> 0 | X25: =SUM(Y25:AB25) -> 0 | Y25: =IFERROR(GETPIVOTDATA("Area AGM",'Pvt OS'!$U$8,"Dealer",""&$S$18&"","Model",""&$S25&""),0) -> 0 | Z25: =IFERROR(GETPIVOTDATA("Area AGM",'Pvt OS'!$M$8,"Dealer",""&$S$18&"","Model",""&$S25&""),0) -> 0 | AA25: =IFERROR(GETPIVOTDATA("Area AGM",'Pvt OS'!#REF!,"Dealer",""&$S$18&"","Model",""&$S25&""),0) -> 0 | AB25: =IFERROR(GETPIVOTDATA("Area AGM",'Pvt OS'!$AO$8,"Dealer",""&$S$18&"","Model",""&$S25&""),0) -> 0 | AC25: =IFERROR(GETPIVOTDATA("Stock",#REF!,"Dealer",""&$S$18&"","Model",""&$S25&""),0) -> 0 | AD25: =IFERROR(GETPIVOTDATA("MDP",#REF!,"Dealer",""&$S$18&"","Model",""&$S25&""),0) -> 0 | AE25: =IFERROR(GETPIVOTDATA("RRN",#REF!,"Model2",""&$S25&"","Dealer",""&$S$18&""),0) -> 0 | AF25: =IFERROR(GETPIVOTDATA("CO",#REF!,"Dealer Name",""&$S$18&"","Model",""&$S25&""),0) -> 0 | AG25: =IFERROR(GETPIVOTDATA("Sum of Distplan Final",#REF!,"Dealer",""&$S$18&"","Model",""&$S25&""),0) -> 0 | AH25: =IFERROR(GETPIVOTDATA("RRN",#REF!,"Model",""&$S25&"","Dealer",""&$S$18&""),0) -> 0 | AI25: =AC25+AD25+AF25+AG25-AH25 -> 0 | AJ25: =IFERROR(GETPIVOTDATA("volume_rs",#REF!,"Model",""&$S25&"","Dealer",""&$S$18&""),0) -> 0 | AK25: =AI25-AJ25-X25+AN25 -> 0 | AL25: =IFERROR(GETPIVOTDATA("Area AGM",'Pvt OS'!#REF!,"Dealer",""&$S$18&"","Model",""&$S25&""),0) -> 0 | AM25: =AK25+AL25 -> 0 | AN25: =IFERROR(GETPIVOTDATA("Row Labels",#REF!,"Dealer",""&$S$18&"","Model",""&$S25&""),0) -> 0 | AO25: =IFERROR(GETPIVOTDATA("RS Afi",#REF!,"Dealer",""&$S$18&"","Model",""&$S25&""),0) -> 0 | AP25: =IFERROR(GETPIVOTDATA("qty",#REF!,"Model",""&$S25&"","Dealer",""&$S$18&""),0) -> 0 | AQ25: =IFERROR(GETPIVOTDATA("volume_rs",#REF!,"Model",""&$S25&"","Dealer",""&$S$18&""),0) -> 0 | AR25: =AP25-AQ25 -> 0 | AS25: =IFERROR(GETPIVOTDATA("Area AGM",'Pvt OS'!#REF!,"Dealer",""&$S$18&"","Model",""&$S25&""),0) -> 0 | AT25: =AR25-AS25 -> 0 | BA25: =#REF! -> #REF! | BB25: =#REF! -> #REF! | BC25: =#REF! -> #REF! | BD25: =#REF! -> #REF!
B26: CAMRY | C26: =SUM(D26:G26) -> 0 | D26: =IFERROR(GETPIVOTDATA("Area AGM",#REF!,"Dealer",""&$S$18&"","Model",""&$B26&"","Umur Outstansing",""&D$2&""),0) -> 0 | E26: =IFERROR(GETPIVOTDATA("Area AGM",#REF!,"Dealer",""&$S$18&"","Model",""&$B26&"","Umur Outstansing",""&E$2&""),0) -> 0 | F26: =IFERROR(GETPIVOTDATA("Area AGM",#REF!,"Dealer",""&$S$18&"","Model",""&$B26&"","Umur Outstansing",""&F$2&""),0) -> 0 | G26: =IFERROR(GETPIVOTDATA("Area AGM",#REF!,"Dealer",""&$S$18&"","Model",""&$B26&"","Umur Outstansing",""&G$2&""),0) -> 0 | H26: =IFERROR(GETPIVOTDATA("Area AGM",#REF!,"Dealer",""&$S$18&"","Model",""&$B26&"","Umur Outstansing",""&H$2&""),0) -> 0 | J26: =IFERROR(GETPIVOTDATA("Area AGM",#REF!,"Dealer",""&$S$18&"","Model",""&$B26&""),0) -> 0 | K26: =IFERROR(GETPIVOTDATA("Area AGM",#REF!,"Dealer",""&$S$18&"","Model",""&$B26&""),0) -> 0 | P26: Yaris | Q26: =IFERROR(R26/AI26,0) -> 0 | R26: =IFERROR(GETPIVOTDATA("RS Target",#REF!,"Dealer",""&$S$18&"","Model",""&$P26&""),0) -> 0 | S26: Yaris | T26: =SUM(Y26:AB26,AO26) -> 0 | U26: =IFERROR(GETPIVOTDATA("Area AGM",'Pvt OS'!#REF!,"Dealer",""&$S$18&"","Model",""&$S26&""),0) -> 0 | V26: =W26-X26 -> 0 | W26: =IFERROR(GETPIVOTDATA("Area AGM",'Pvt OS'!#REF!,"Dealer",""&$S$18&"","Model",""&$S26&""),0)+IFERROR(GETPIVOTDATA("Area AGM",'Pvt OS'!$A$8,"Dealer",""&$S$18&"","Model",""&$S26&""),0) -> 0 | X26: =SUM(Y26:AB26) -> 0 | Y26: =IFERROR(GETPIVOTDATA("Area AGM",'Pvt OS'!$U$8,"Dealer",""&$S$18&"","Model",""&$S26&""),0) -> 0 | Z26: =IFERROR(GETPIVOTDATA("Area AGM",'Pvt OS'!$M$8,"Dealer",""&$S$18&"","Model",""&$S26&""),0) -> 0 | AA26: =IFERROR(GETPIVOTDATA("Area AGM",'Pvt OS'!#REF!,"Dealer",""&$S$18&"","Model",""&$S26&""),0) -> 0 | AB26: =IFERROR(GETPIVOTDATA("Area AGM",'Pvt OS'!$AO$8,"Dealer",""&$S$18&"","Model",""&$S26&""),0) -> 0 | AC26: =IFERROR(GETPIVOTDATA("Stock",#REF!,"Dealer",""&$S$18&"","Model",""&$S26&""),0) -> 0 | AD26: =IFERROR(GETPIVOTDATA("MDP",#REF!,"Dealer",""&$S$18&"","Model",""&$S26&""),0) -> 0 | AE26: =IFERROR(GETPIVOTDATA("RRN",#REF!,"Model2",""&$S26&"","Dealer",""&$S$18&""),0) -> 0 | AF26: =IFERROR(GETPIVOTDATA("CO",#REF!,"Dealer Name",""&$S$18&"","Model",""&$S26&""),0) -> 0 | AG26: =IFERROR(GETPIVOTDATA("Sum of Distplan Final",#REF!,"Dealer",""&$S$18&"","Model",""&$S26&""),0) -> 0 | AH26: =IFERROR(GETPIVOTDATA("RRN",#REF!,"Model",""&$S26&"","Dealer",""&$S$18&""),0) -> 0 | AI26: =AC26+AD26+AF26+AG26-AH26 -> 0 | AJ26: =IFERROR(GETPIVOTDATA("volume_rs",#REF!,"Model",""&$S26&"","Dealer",""&$S$18&""),0) -> 0 | AK26: =AI26-AJ26-X26+AN26 -> 0 | AL26: =IFERROR(GETPIVOTDATA("Area AGM",'Pvt OS'!#REF!,"Dealer",""&$S$18&"","Model",""&$S26&""),0) -> 0 | AM26: =AK26+AL26 -> 0 | AN26: =IFERROR(GETPIVOTDATA("Row Labels",#REF!,"Dealer",""&$S$18&"","Model",""&$S26&""),0) -> 0 | AO26: =IFERROR(GETPIVOTDATA("RS Afi",#REF!,"Dealer",""&$S$18&"","Model",""&$S26&""),0) -> 0 | AP26: =IFERROR(GETPIVOTDATA("qty",#REF!,"Model",""&$S26&"","Dealer",""&$S$18&""),0) -> 0 | AQ26: =IFERROR(GETPIVOTDATA("volume_rs",#REF!,"Model",""&$S26&"","Dealer",""&$S$18&""),0) -> 0 | AR26: =AP26-AQ26 -> 0 | AS26: =IFERROR(GETPIVOTDATA("Area AGM",'Pvt OS'!#REF!,"Dealer",""&$S$18&"","Model",""&$S26&""),0) -> 0 | AT26: =AR26-AS26 -> 0 | BA26: =#REF! -> #REF! | BB26: =#REF! -> #REF! | BC26: =#REF! -> #REF! | BD26: =#REF! -> #REF!
B27: DYNA | C27: =SUM(D27:G27) -> 0 | D27: =IFERROR(GETPIVOTDATA("Area AGM",#REF!,"Dealer",""&$S$18&"","Model",""&$B27&"","Umur Outstansing",""&D$2&""),0) -> 0 | E27: =IFERROR(GETPIVOTDATA("Area AGM",#REF!,"Dealer",""&$S$18&"","Model",""&$B27&"","Umur Outstansing",""&E$2&""),0) -> 0 | F27: =IFERROR(GETPIVOTDATA("Area AGM",#REF!,"Dealer",""&$S$18&"","Model",""&$B27&"","Umur Outstansing",""&F$2&""),0) -> 0 | G27: =IFERROR(GETPIVOTDATA("Area AGM",#REF!,"Dealer",""&$S$18&"","Model",""&$B27&"","Umur Outstansing",""&G$2&""),0) -> 0 | H27: =IFERROR(GETPIVOTDATA("Area AGM",#REF!,"Dealer",""&$S$18&"","Model",""&$B27&"","Umur Outstansing",""&H$2&""),0) -> 0 | J27: =IFERROR(GETPIVOTDATA("Area AGM",#REF!,"Dealer",""&$S$18&"","Model",""&$B27&""),0) -> 0 | K27: =IFERROR(GETPIVOTDATA("Area AGM",#REF!,"Dealer",""&$S$18&"","Model",""&$B27&""),0) -> 0 | P27: Innova | Q27: =IFERROR(R27/AI27,0) -> 0 | R27: =IFERROR(GETPIVOTDATA("RS Target",#REF!,"Dealer",""&$S$18&"","Model",""&$P27&""),0) -> 0 | S27: Innova | T27: =SUM(Y27:AB27,AO27) -> 0 | U27: =IFERROR(GETPIVOTDATA("Area AGM",'Pvt OS'!#REF!,"Dealer",""&$S$18&"","Model",""&$S27&""),0) -> 0 | V27: =W27-X27 -> 0 | W27: =IFERROR(GETPIVOTDATA("Area AGM",'Pvt OS'!#REF!,"Dealer",""&$S$18&"","Model",""&$S27&""),0)+IFERROR(GETPIVOTDATA("Area AGM",'Pvt OS'!$A$8,"Dealer",""&$S$18&"","Model",""&$S27&""),0) -> 0 | X27: =SUM(Y27:AB27) -> 0 | Y27: =IFERROR(GETPIVOTDATA("Area AGM",'Pvt OS'!$U$8,"Dealer",""&$S$18&"","Model",""&$S27&""),0) -> 0 | Z27: =IFERROR(GETPIVOTDATA("Area AGM",'Pvt OS'!$M$8,"Dealer",""&$S$18&"","Model",""&$S27&""),0) -> 0 | AA27: =IFERROR(GETPIVOTDATA("Area AGM",'Pvt OS'!#REF!,"Dealer",""&$S$18&"","Model",""&$S27&""),0) -> 0 | AB27: =IFERROR(GETPIVOTDATA("Area AGM",'Pvt OS'!$AO$8,"Dealer",""&$S$18&"","Model",""&$S27&""),0) -> 0 | AC27: =IFERROR(GETPIVOTDATA("Stock",#REF!,"Dealer",""&$S$18&"","Model",""&$S27&""),0) -> 0 | AD27: =IFERROR(GETPIVOTDATA("MDP",#REF!,"Dealer",""&$S$18&"","Model",""&$S27&""),0) -> 0 | AE27: =IFERROR(GETPIVOTDATA("RRN",#REF!,"Model2",""&$S27&"","Dealer",""&$S$18&""),0) -> 0 | AF27: =IFERROR(GETPIVOTDATA("CO",#REF!,"Dealer Name",""&$S$18&"","Model",""&$S27&""),0) -> 0 | AG27: =IFERROR(GETPIVOTDATA("Sum of Distplan Final",#REF!,"Dealer",""&$S$18&"","Model",""&$S27&""),0) -> 0 | AH27: =IFERROR(GETPIVOTDATA("RRN",#REF!,"Model",""&$S27&"","Dealer",""&$S$18&""),0) -> 0 | AI27: =AC27+AD27+AF27+AG27-AH27 -> 0 | AJ27: =IFERROR(GETPIVOTDATA("volume_rs",#REF!,"Model",""&$S27&"","Dealer",""&$S$18&""),0) -> 0 | AK27: =AI27-AJ27-X27+AN27 -> 0 | AL27: =IFERROR(GETPIVOTDATA("Area AGM",'Pvt OS'!#REF!,"Dealer",""&$S$18&"","Model",""&$S27&""),0) -> 0 | AM27: =AK27+AL27 -> 0 | AN27: =IFERROR(GETPIVOTDATA("Row Labels",#REF!,"Dealer",""&$S$18&"","Model",""&$S27&""),0) -> 0 | AO27: =IFERROR(GETPIVOTDATA("RS Afi",#REF!,"Dealer",""&$S$18&"","Model",""&$S27&""),0) -> 0 | AP27: =IFERROR(GETPIVOTDATA("qty",#REF!,"Model",""&$S27&"","Dealer",""&$S$18&""),0) -> 0 | AQ27: =IFERROR(GETPIVOTDATA("volume_rs",#REF!,"Model",""&$S27&"","Dealer",""&$S$18&""),0) -> 0 | AR27: =AP27-AQ27 -> 0 | AS27: =IFERROR(GETPIVOTDATA("Area AGM",'Pvt OS'!#REF!,"Dealer",""&$S$18&"","Model",""&$S27&""),0) -> 0 | AT27: =AR27-AS27 -> 0 | BA27: =#REF! -> #REF! | BB27: =#REF! -> #REF! | BC27: =#REF! -> #REF! | BD27: =#REF! -> #REF!
B28: FORTUNER 4X4 | C28: =SUM(D28:G28) -> 0 | D28: =IFERROR(GETPIVOTDATA("Area AGM",#REF!,"Dealer",""&$S$18&"","Model",""&$B28&"","Umur Outstansing",""&D$2&""),0) -> 0 | E28: =IFERROR(GETPIVOTDATA("Area AGM",#REF!,"Dealer",""&$S$18&"","Model",""&$B28&"","Umur Outstansing",""&E$2&""),0) -> 0 | F28: =IFERROR(GETPIVOTDATA("Area AGM",#REF!,"Dealer",""&$S$18&"","Model",""&$B28&"","Umur Outstansing",""&F$2&""),0) -> 0 | G28: =IFERROR(GETPIVOTDATA("Area AGM",#REF!,"Dealer",""&$S$18&"","Model",""&$B28&"","Umur Outstansing",""&G$2&""),0) -> 0 | H28: =IFERROR(GETPIVOTDATA("Area AGM",#REF!,"Dealer",""&$S$18&"","Model",""&$B28&"","Umur Outstansing",""&H$2&""),0) -> 0 | J28: =IFERROR(GETPIVOTDATA("Area AGM",#REF!,"Dealer",""&$S$18&"","Model",""&$B28&""),0) -> 0 | K28: =IFERROR(GETPIVOTDATA("Area AGM",#REF!,"Dealer",""&$S$18&"","Model",""&$B28&""),0) -> 0 | P28: Fortuner 4x2 | Q28: =IFERROR(R28/AI28,0) -> 0 | R28: =IFERROR(GETPIVOTDATA("RS Target",#REF!,"Dealer",""&$S$18&"","Model",""&$P28&""),0) -> 0 | S28: Fortuner 4x2 | T28: =SUM(Y28:AB28,AO28) -> 0 | U28: =IFERROR(GETPIVOTDATA("Area AGM",'Pvt OS'!#REF!,"Dealer",""&$S$18&"","Model",""&$S28&""),0) -> 0 | V28: =W28-X28 -> 0 | W28: =IFERROR(GETPIVOTDATA("Area AGM",'Pvt OS'!#REF!,"Dealer",""&$S$18&"","Model",""&$S28&""),0)+IFERROR(GETPIVOTDATA("Area AGM",'Pvt OS'!$A$8,"Dealer",""&$S$18&"","Model",""&$S28&""),0) -> 0 | X28: =SUM(Y28:AB28) -> 0 | Y28: =IFERROR(GETPIVOTDATA("Area AGM",'Pvt OS'!$U$8,"Dealer",""&$S$18&"","Model",""&$S28&""),0) -> 0 | Z28: =IFERROR(GETPIVOTDATA("Area AGM",'Pvt OS'!$M$8,"Dealer",""&$S$18&"","Model",""&$S28&""),0) -> 0 | AA28: =IFERROR(GETPIVOTDATA("Area AGM",'Pvt OS'!#REF!,"Dealer",""&$S$18&"","Model",""&$S28&""),0) -> 0 | AB28: =IFERROR(GETPIVOTDATA("Area AGM",'Pvt OS'!$AO$8,"Dealer",""&$S$18&"","Model",""&$S28&""),0) -> 0 | AC28: =IFERROR(GETPIVOTDATA("Stock",#REF!,"Dealer",""&$S$18&"","Model",""&$S28&""),0) -> 0 | AD28: =IFERROR(GETPIVOTDATA("MDP",#REF!,"Dealer",""&$S$18&"","Model",""&$S28&""),0) -> 0 | AE28: =IFERROR(GETPIVOTDATA("RRN",#REF!,"Model2",""&$S28&"","Dealer",""&$S$18&""),0) -> 0 | AF28: =IFERROR(GETPIVOTDATA("CO",#REF!,"Dealer Name",""&$S$18&"","Model",""&$S28&""),0) -> 0 | AG28: =IFERROR(GETPIVOTDATA("Sum of Distplan Final",#REF!,"Dealer",""&$S$18&"","Model",""&$S28&""),0) -> 0 | AH28: =IFERROR(GETPIVOTDATA("RRN",#REF!,"Model",""&$S28&"","Dealer",""&$S$18&""),0) -> 0 | AI28: =AC28+AD28+AF28+AG28-AH28 -> 0 | AJ28: =IFERROR(GETPIVOTDATA("volume_rs",#REF!,"Model",""&$S28&"","Dealer",""&$S$18&""),0) -> 0 | AK28: =AI28-AJ28-X28+AN28 -> 0 | AL28: =IFERROR(GETPIVOTDATA("Area AGM",'Pvt OS'!#REF!,"Dealer",""&$S$18&"","Model",""&$S28&""),0) -> 0 | AM28: =AK28+AL28 -> 0 | AN28: =IFERROR(GETPIVOTDATA("Row Labels",#REF!,"Dealer",""&$S$18&"","Model",""&$S28&""),0) -> 0 | AO28: =IFERROR(GETPIVOTDATA("RS Afi",#REF!,"Dealer",""&$S$18&"","Model",""&$S28&""),0) -> 0 | AP28: =IFERROR(GETPIVOTDATA("qty",#REF!,"Model",""&$S28&"","Dealer",""&$S$18&""),0) -> 0 | AQ28: =IFERROR(GETPIVOTDATA("volume_rs",#REF!,"Model",""&$S28&"","Dealer",""&$S$18&""),0) -> 0 | AR28: =AP28-AQ28 -> 0 | AS28: =IFERROR(GETPIVOTDATA("Area AGM",'Pvt OS'!#REF!,"Dealer",""&$S$18&"","Model",""&$S28&""),0) -> 0 | AT28: =AR28-AS28 -> 0 | BA28: =#REF! -> #REF! | BB28: =#REF! -> #REF! | BC28: =#REF! -> #REF! | BD28: =#REF! -> #REF!
B29: HIACE | C29: =SUM(D29:G29) -> 0 | D29: =IFERROR(GETPIVOTDATA("Area AGM",#REF!,"Dealer",""&$S$18&"","Model",""&$B29&"","Umur Outstansing",""&D$2&""),0) -> 0 | E29: =IFERROR(GETPIVOTDATA("Area AGM",#REF!,"Dealer",""&$S$18&"","Model",""&$B29&"","Umur Outstansing",""&E$2&""),0) -> 0 | F29: =IFERROR(GETPIVOTDATA("Area AGM",#REF!,"Dealer",""&$S$18&"","Model",""&$B29&"","Umur Outstansing",""&F$2&""),0) -> 0 | G29: =IFERROR(GETPIVOTDATA("Area AGM",#REF!,"Dealer",""&$S$18&"","Model",""&$B29&"","Umur Outstansing",""&G$2&""),0) -> 0 | H29: =IFERROR(GETPIVOTDATA("Area AGM",#REF!,"Dealer",""&$S$18&"","Model",""&$B29&"","Umur Outstansing",""&H$2&""),0) -> 0 | J29: =IFERROR(GETPIVOTDATA("Area AGM",#REF!,"Dealer",""&$S$18&"","Model",""&$B29&""),0) -> 0 | K29: =IFERROR(GETPIVOTDATA("Area AGM",#REF!,"Dealer",""&$S$18&"","Model",""&$B29&""),0) -> 0 | P29: Rush | Q29: =IFERROR(R29/AI29,0) -> 0 | R29: =IFERROR(GETPIVOTDATA("RS Target",#REF!,"Dealer",""&$S$18&"","Model",""&$P29&""),0) -> 0 | S29: Rush | T29: =SUM(Y29:AB29,AO29) -> 0 | U29: =IFERROR(GETPIVOTDATA("Area AGM",'Pvt OS'!#REF!,"Dealer",""&$S$18&"","Model",""&$S29&""),0) -> 0 | V29: =W29-X29 -> 0 | W29: =IFERROR(GETPIVOTDATA("Area AGM",'Pvt OS'!#REF!,"Dealer",""&$S$18&"","Model",""&$S29&""),0)+IFERROR(GETPIVOTDATA("Area AGM",'Pvt OS'!$A$8,"Dealer",""&$S$18&"","Model",""&$S29&""),0) -> 0 | X29: =SUM(Y29:AB29) -> 0 | Y29: =IFERROR(GETPIVOTDATA("Area AGM",'Pvt OS'!$U$8,"Dealer",""&$S$18&"","Model",""&$S29&""),0) -> 0 | Z29: =IFERROR(GETPIVOTDATA("Area AGM",'Pvt OS'!$M$8,"Dealer",""&$S$18&"","Model",""&$S29&""),0) -> 0 | AA29: =IFERROR(GETPIVOTDATA("Area AGM",'Pvt OS'!#REF!,"Dealer",""&$S$18&"","Model",""&$S29&""),0) -> 0 | AB29: =IFERROR(GETPIVOTDATA("Area AGM",'Pvt OS'!$AO$8,"Dealer",""&$S$18&"","Model",""&$S29&""),0) -> 0 | AC29: =IFERROR(GETPIVOTDATA("Stock",#REF!,"Dealer",""&$S$18&"","Model",""&$S29&""),0) -> 0 | AD29: =IFERROR(GETPIVOTDATA("MDP",#REF!,"Dealer",""&$S$18&"","Model",""&$S29&""),0) -> 0 | AE29: =IFERROR(GETPIVOTDATA("RRN",#REF!,"Model2",""&$S29&"","Dealer",""&$S$18&""),0) -> 0 | AF29: =IFERROR(GETPIVOTDATA("CO",#REF!,"Dealer Name",""&$S$18&"","Model",""&$S29&""),0) -> 0 | AG29: =IFERROR(GETPIVOTDATA("Sum of Distplan Final",#REF!,"Dealer",""&$S$18&"","Model",""&$S29&""),0) -> 0 | AH29: =IFERROR(GETPIVOTDATA("RRN",#REF!,"Model",""&$S29&"","Dealer",""&$S$18&""),0) -> 0 | AI29: =AC29+AD29+AF29+AG29-AH29 -> 0 | AJ29: =IFERROR(GETPIVOTDATA("volume_rs",#REF!,"Model",""&$S29&"","Dealer",""&$S$18&""),0) -> 0 | AK29: =AI29-AJ29-X29+AN29 -> 0 | AL29: =IFERROR(GETPIVOTDATA("Area AGM",'Pvt OS'!#REF!,"Dealer",""&$S$18&"","Model",""&$S29&""),0) -> 0 | AM29: =AK29+AL29 -> 0 | AN29: =IFERROR(GETPIVOTDATA("Row Labels",#REF!,"Dealer",""&$S$18&"","Model",""&$S29&""),0) -> 0 | AO29: =IFERROR(GETPIVOTDATA("RS Afi",#REF!,"Dealer",""&$S$18&"","Model",""&$S29&""),0) -> 0 | AP29: =IFERROR(GETPIVOTDATA("qty",#REF!,"Model",""&$S29&"","Dealer",""&$S$18&""),0) -> 0 | AQ29: =IFERROR(GETPIVOTDATA("volume_rs",#REF!,"Model",""&$S29&"","Dealer",""&$S$18&""),0) -> 0 | AR29: =AP29-AQ29 -> 0 | AS29: =IFERROR(GETPIVOTDATA("Area AGM",'Pvt OS'!#REF!,"Dealer",""&$S$18&"","Model",""&$S29&""),0) -> 0 | AT29: =AR29-AS29 -> 0 | BA29: =#REF! -> #REF! | BB29: =#REF! -> #REF! | BC29: =#REF! -> #REF! | BD29: =#REF! -> #REF!
B30: HILUX D-CAB | C30: =SUM(D30:G30) -> 0 | D30: =IFERROR(GETPIVOTDATA("Area AGM",#REF!,"Dealer",""&$S$18&"","Model",""&$B30&"","Umur Outstansing",""&D$2&""),0) -> 0 | E30: =IFERROR(GETPIVOTDATA("Area AGM",#REF!,"Dealer",""&$S$18&"","Model",""&$B30&"","Umur Outstansing",""&E$2&""),0) -> 0 | F30: =IFERROR(GETPIVOTDATA("Area AGM",#REF!,"Dealer",""&$S$18&"","Model",""&$B30&"","Umur Outstansing",""&F$2&""),0) -> 0 | G30: =IFERROR(GETPIVOTDATA("Area AGM",#REF!,"Dealer",""&$S$18&"","Model",""&$B30&"","Umur Outstansing",""&G$2&""),0) -> 0 | H30: =IFERROR(GETPIVOTDATA("Area AGM",#REF!,"Dealer",""&$S$18&"","Model",""&$B30&"","Umur Outstansing",""&H$2&""),0) -> 0 | J30: =IFERROR(GETPIVOTDATA("Area AGM",#REF!,"Dealer",""&$S$18&"","Model",""&$B30&""),0) -> 0 | K30: =IFERROR(GETPIVOTDATA("Area AGM",#REF!,"Dealer",""&$S$18&"","Model",""&$B30&""),0) -> 0 | P30: Others | Q30: =IFERROR(R30/AI30,0) -> 0 | R30: =R31-SUM(R21:R29) -> 0 | S30: Others | T30: =SUM(Y30:AB30,AO30) -> 0 | U30: =U31-SUM(U21:U29) -> 0 | V30: =W30-X30 -> 0 | W30: =W31-SUM(W21:W29) -> 0 | X30: =SUM(Y30:AB30) -> 0 | Y30: =Y31-SUM(Y21:Y29) -> 0 | Z30: =Z31-SUM(Z21:Z29) -> 0 | AA30: =AA31-SUM(AA21:AA29) -> 0 | AB30: =AB31-SUM(AB21:AB29) -> 0 | AC30: =AC31-SUM(AC21:AC29) -> 0 | AD30: =AD31-SUM(AD21:AD29) -> 0 | AE30: =AE31-SUM(AE21:AE29) -> 0 | AF30: =AF31-SUM(AF21:AF29) -> 0 | ... AH30: =AH31-SUM(AH21:AH29) -> 0 | AI30: =AC30+AD30+AF30+AG30-AH30 -> 0 | AJ30: =AJ31-SUM(AJ21:AJ29) -> 0 | AK30: =AI30-AJ30-X30+AN30 -> 0 | AL30: =AL31-SUM(AL21:AL29) -> 0 | AM30: =AK30+AL30 -> 0 | AN30: =AN31-SUM(AN21:AN29) -> 0 | AO30: =AO31-SUM(AO21:AO29) -> 0 | AP30: =AP31-SUM(AP21:AP29) -> 0 | AQ30: =AQ31-SUM(AQ21:AQ29) -> 0 | AR30: =AP30-AQ30 -> 0 | AS30: =AS31-SUM(AS21:AS29) -> 0 | AT30: =AR30-AS30 -> 0 | BA30: =#REF! -> #REF! | BB30: =#REF! -> #REF! | BC30: =#REF! -> #REF! | BD30: =#REF! -> #REF!
B31: HILUX S-CAB | C31: =SUM(D31:G31) -> 0 | D31: =IFERROR(GETPIVOTDATA("Area AGM",#REF!,"Dealer",""&$S$18&"","Model",""&$B31&"","Umur Outstansing",""&D$2&""),0) -> 0 | E31: =IFERROR(GETPIVOTDATA("Area AGM",#REF!,"Dealer",""&$S$18&"","Model",""&$B31&"","Umur Outstansing",""&E$2&""),0) -> 0 | F31: =IFERROR(GETPIVOTDATA("Area AGM",#REF!,"Dealer",""&$S$18&"","Model",""&$B31&"","Umur Outstansing",""&F$2&""),0) -> 0 | G31: =IFERROR(GETPIVOTDATA("Area AGM",#REF!,"Dealer",""&$S$18&"","Model",""&$B31&"","Umur Outstansing",""&G$2&""),0) -> 0 | H31: =IFERROR(GETPIVOTDATA("Area AGM",#REF!,"Dealer",""&$S$18&"","Model",""&$B31&"","Umur Outstansing",""&H$2&""),0) -> 0 | J31: =IFERROR(GETPIVOTDATA("Area AGM",#REF!,"Dealer",""&$S$18&"","Model",""&$B31&""),0) -> 0 | K31: =IFERROR(GETPIVOTDATA("Area AGM",#REF!,"Dealer",""&$S$18&"","Model",""&$B31&""),0) -> 0 | P31: Grand Total | Q31: =IFERROR(R31/AI31,0) -> 0 | R31: =IFERROR(GETPIVOTDATA("RS Target",#REF!,"Dealer",""&$S$18&""),0) -> 0 | S31: Grand Total | T31: =SUM(Y31:AB31,AO31) -> 0 | U31: =IFERROR(GETPIVOTDATA("Area AGM",'Pvt OS'!#REF!,"Dealer",""&$S$18&""),0) -> 0 | V31: =W31-X31 -> 0 | W31: =IFERROR(GETPIVOTDATA("Area AGM",'Pvt OS'!#REF!,"Dealer",""&$S$18&""),0)+IFERROR(GETPIVOTDATA("Area AGM",'Pvt OS'!$A$8,"Dealer",""&$S$18&""),0) -> 0 | X31: =SUM(Y31:AB31) -> 0 | Y31: =IFERROR(GETPIVOTDATA("Area AGM",'Pvt OS'!$U$8,"Dealer",""&$S$18&""),0) -> 0 | Z31: =IFERROR(GETPIVOTDATA("Area AGM",'Pvt OS'!$M$8,"Dealer",""&$S$18&""),0) -> 0 | AA31: =IFERROR(GETPIVOTDATA("Area AGM",'Pvt OS'!#REF!,"Dealer",""&$S$18&""),0) -> 0 | AB31: =IFERROR(GETPIVOTDATA("Area AGM",'Pvt OS'!$AO$8,"Dealer",""&$S$18&""),0) -> 0 | AC31: =IFERROR(GETPIVOTDATA("Stock",#REF!,"Dealer",""&$S$18&""),0) -> 0 | AD31: =IFERROR(GETPIVOTDATA("MDP",#REF!,"Dealer",""&$S$18&""),0) -> 0 | AE31: =IFERROR(GETPIVOTDATA("RRN",#REF!,"Dealer",""&$S$18&""),0) -> 0 | AF31: =IFERROR(GETPIVOTDATA("CO",#REF!,"Dealer Name",""&$S$18&""),0) -> 0 | AG31: =IFERROR(GETPIVOTDATA("Sum of Distplan Final",#REF!,"Dealer",""&$S$18&""),0) -> 0 | AH31: =IFERROR(GETPIVOTDATA("RRN",#REF!,"Dealer",""&$S$18&""),0) -> 0 | AI31: =AC31+AD31+AF31+AG31-AH31 -> 0 | AJ31: =IFERROR(GETPIVOTDATA("volume_rs",#REF!,"Dealer",""&$S$18&""),0) -> 0 | AK31: =AI31-AJ31-X31+AN31 -> 0 | AL31: =IFERROR(GETPIVOTDATA("Area AGM",'Pvt OS'!#REF!,"Dealer",""&$S$18&""),0) -> 0 | AM31: ='AO Report(0)'!#REF! -> #REF! | AN31: =IFERROR(GETPIVOTDATA("Row Labels",#REF!,"Dealer",""&$S$18&""),0) -> 0 | AO31: =IFERROR(GETPIVOTDATA("RS Afi",#REF!,"Dealer",""&$S$18&""),0) -> 0 | AP31: =IFERROR(GETPIVOTDATA("qty",#REF!,"Dealer",""&$S$18&""),0) -> 0 | AQ31: =IFERROR(GETPIVOTDATA("volume_rs",#REF!,"Dealer",""&$S$18&""),0) -> 0 | AR31: =AP31-AQ31 -> 0 | AS31: =IFERROR(GETPIVOTDATA("Area AGM",'Pvt OS'!#REF!,"Dealer",""&$S$18&""),0) -> 0 | AT31: =AR31-AS31 -> 0 | BA31: =#REF! -> #REF! | BB31: =#REF! -> #REF! | BC31: =#REF! -> #REF! | BD31: =#REF! -> #REF!
B32: TRANSMOVER | C32: =SUM(D32:G32) -> 0 | D32: =IFERROR(GETPIVOTDATA("Area AGM",#REF!,"Dealer",""&$S$18&"","Model",""&$B32&"","Umur Outstansing",""&D$2&""),0) -> 0 | E32: =IFERROR(GETPIVOTDATA("Area AGM",#REF!,"Dealer",""&$S$18&"","Model",""&$B32&"","Umur Outstansing",""&E$2&""),0) -> 0 | F32: =IFERROR(GETPIVOTDATA("Area AGM",#REF!,"Dealer",""&$S$18&"","Model",""&$B32&"","Umur Outstansing",""&F$2&""),0) -> 0 | G32: =IFERROR(GETPIVOTDATA("Area AGM",#REF!,"Dealer",""&$S$18&"","Model",""&$B32&"","Umur Outstansing",""&G$2&""),0) -> 0 | H32: =IFERROR(GETPIVOTDATA("Area AGM",#REF!,"Dealer",""&$S$18&"","Model",""&$B32&"","Umur Outstansing",""&H$2&""),0) -> 0 | J32: =IFERROR(GETPIVOTDATA("Area AGM",#REF!,"Dealer",""&$S$18&"","Model",""&$B32&""),0) -> 0 | K32: =IFERROR(GETPIVOTDATA("Area AGM",#REF!,"Dealer",""&$S$18&"","Model",""&$B32&""),0) -> 0
B33: VELLFIRE | C33: =SUM(D33:G33) -> 0 | D33: =IFERROR(GETPIVOTDATA("Area AGM",#REF!,"Dealer",""&$S$18&"","Model",""&$B33&"","Umur Outstansing",""&D$2&""),0) -> 0 | E33: =IFERROR(GETPIVOTDATA("Area AGM",#REF!,"Dealer",""&$S$18&"","Model",""&$B33&"","Umur Outstansing",""&E$2&""),0) -> 0 | F33: =IFERROR(GETPIVOTDATA("Area AGM",#REF!,"Dealer",""&$S$18&"","Model",""&$B33&"","Umur Outstansing",""&F$2&""),0) -> 0 | G33: =IFERROR(GETPIVOTDATA("Area AGM",#REF!,"Dealer",""&$S$18&"","Model",""&$B33&"","Umur Outstansing",""&G$2&""),0) -> 0 | H33: =IFERROR(GETPIVOTDATA("Area AGM",#REF!,"Dealer",""&$S$18&"","Model",""&$B33&"","Umur Outstansing",""&H$2&""),0) -> 0 | J33: =IFERROR(GETPIVOTDATA("Area AGM",#REF!,"Dealer",""&$S$18&"","Model",""&$B33&""),0) -> 0 | K33: =IFERROR(GETPIVOTDATA("Area AGM",#REF!,"Dealer",""&$S$18&"","Model",""&$B33&""),0) -> 0 | R33: =R34=R30 -> TRUE | T33: =T34=T30 -> TRUE | U33: =U34=U30 -> TRUE | V33: =V34=V30 -> TRUE | W33: =W34=W30 -> TRUE | X33: =X34=X30 -> TRUE | Y33: =Y34=Y30 -> TRUE | Z33: =Z34=Z30 -> TRUE | AA33: =AA34=AA30 -> TRUE | ... AT33: =AT34=AT30 -> TRUE
B34: VIOS | C34: =SUM(D34:G34) -> 0 | D34: =IFERROR(GETPIVOTDATA("Area AGM",#REF!,"Dealer",""&$S$18&"","Model",""&$B34&"","Umur Outstansing",""&D$2&""),0) -> 0 | E34: =IFERROR(GETPIVOTDATA("Area AGM",#REF!,"Dealer",""&$S$18&"","Model",""&$B34&"","Umur Outstansing",""&E$2&""),0) -> 0 | F34: =IFERROR(GETPIVOTDATA("Area AGM",#REF!,"Dealer",""&$S$18&"","Model",""&$B34&"","Umur Outstansing",""&F$2&""),0) -> 0 | G34: =IFERROR(GETPIVOTDATA("Area AGM",#REF!,"Dealer",""&$S$18&"","Model",""&$B34&"","Umur Outstansing",""&G$2&""),0) -> 0 | H34: =IFERROR(GETPIVOTDATA("Area AGM",#REF!,"Dealer",""&$S$18&"","Model",""&$B34&"","Umur Outstansing",""&H$2&""),0) -> 0 | J34: =IFERROR(GETPIVOTDATA("Area AGM",#REF!,"Dealer",""&$S$18&"","Model",""&$B34&""),0) -> 0 | K34: =IFERROR(GETPIVOTDATA("Area AGM",#REF!,"Dealer",""&$S$18&"","Model",""&$B34&""),0) -> 0 | Q34: =IFERROR(R34/AI34,0) -> 0 | R34: =SUM(R35:R67) -> 0 | T34: =SUM(T35:T67) -> 0 | U34: =SUM(U35:U67) -> 0 | V34: =SUM(V35:V67) -> 0 | W34: =SUM(W35:W67) -> 0 | X34: =SUM(X35:X67) -> 0 | Y34: =SUM(Y35:Y67) -> 0 | Z34: =SUM(Z35:Z67) -> 0 | AA34: =SUM(AA35:AA67) -> 0 | ... AT34: =SUM(AT35:AT67) -> 0
B35: VOXY | C35: =SUM(D35:G35) -> 0 | D35: =IFERROR(GETPIVOTDATA("Area AGM",#REF!,"Dealer",""&$S$18&"","Model",""&$B35&"","Umur Outstansing",""&D$2&""),0) -> 0 | E35: =IFERROR(GETPIVOTDATA("Area AGM",#REF!,"Dealer",""&$S$18&"","Model",""&$B35&"","Umur Outstansing",""&E$2&""),0) -> 0 | F35: =IFERROR(GETPIVOTDATA("Area AGM",#REF!,"Dealer",""&$S$18&"","Model",""&$B35&"","Umur Outstansing",""&F$2&""),0) -> 0 | G35: =IFERROR(GETPIVOTDATA("Area AGM",#REF!,"Dealer",""&$S$18&"","Model",""&$B35&"","Umur Outstansing",""&G$2&""),0) -> 0 | H35: =IFERROR(GETPIVOTDATA("Area AGM",#REF!,"Dealer",""&$S$18&"","Model",""&$B35&"","Umur Outstansing",""&H$2&""),0) -> 0 | J35: =IFERROR(GETPIVOTDATA("Area AGM",#REF!,"Dealer",""&$S$18&"","Model",""&$B35&""),0) -> 0 | K35: =IFERROR(GETPIVOTDATA("Area AGM",#REF!,"Dealer",""&$S$18&"","Model",""&$B35&""),0) -> 0 | P35: ALPHARD | Q35: =IFERROR(R35/AI35,0) -> 0 | R35: =IFERROR(GETPIVOTDATA("RS Target",#REF!,"Dealer",""&$S$18&"","Model",""&$P35&""),0) -> 0 | S35: ALPHARD | T35: =SUM(Y35:AB35,AO35) -> 0 | U35: =IFERROR(GETPIVOTDATA("Area AGM",'Pvt OS'!#REF!,"Dealer",""&$S$18&"","Model",""&$S35&""),0) -> 0 | V35: =W35-X35 -> 0 | W35: =IFERROR(GETPIVOTDATA("Area AGM",'Pvt OS'!#REF!,"Dealer",""&$S$18&"","Model",""&$S35&""),0)+IFERROR(GETPIVOTDATA("Area AGM",'Pvt OS'!$A$8,"Dealer",""&$S$18&"","Model",""&$S35&""),0) -> 0 | X35: =SUM(Y35:AB35) -> 0 | Y35: =IFERROR(GETPIVOTDATA("Area AGM",'Pvt OS'!$U$8,"Dealer",""&$S$18&"","Model",""&$S35&""),0) -> 0 | Z35: =IFERROR(GETPIVOTDATA("Area AGM",'Pvt OS'!$M$8,"Dealer",""&$S$18&"","Model",""&$S35&""),0) -> 0 | AA35: =IFERROR(GETPIVOTDATA("Area AGM",'Pvt OS'!#REF!,"Dealer",""&$S$18&"","Model",""&$S35&""),0) -> 0 | AB35: =IFERROR(GETPIVOTDATA("Area AGM",'Pvt OS'!$AO$8,"Dealer",""&$S$18&"","Model",""&$S35&""),0) -> 0 | AC35: =IFERROR(GETPIVOTDATA("Stock",#REF!,"Dealer",""&$S$18&"","Model",""&$S35&""),0) -> 0 | AD35: =IFERROR(GETPIVOTDATA("MDP",#REF!,"Dealer",""&$S$18&"","Model",""&$S35&""),0) -> 0 | AE35: =IFERROR(GETPIVOTDATA("RRN",#REF!,"Model2",""&$S35&"","Dealer",""&$S$18&""),0) -> 0 | AF35: =IFERROR(GETPIVOTDATA("CO",#REF!,"Dealer Name",""&$S$18&"","Model",""&$S35&""),0) -> 0 | AG35: =IFERROR(GETPIVOTDATA("Sum of Distplan Final",#REF!,"Dealer",""&$S$18&"","Model",""&$S35&""),0) -> 0 | AH35: =IFERROR(GETPIVOTDATA("RRN",#REF!,"Model",""&$S35&"","Dealer",""&$S$18&""),0) -> 0 | AI35: =AC35+AD35+AF35+AG35-AH35 -> 0 | AJ35: =IFERROR(GETPIVOTDATA("volume_rs",#REF!,"Model",""&$S35&"","Dealer",""&$S$18&""),0) -> 0 | AK35: =AI35-AJ35-X35+AN35 -> 0 | AL35: =IFERROR(GETPIVOTDATA("Area AGM",'Pvt OS'!#REF!,"Dealer",""&$S$18&"","Model",""&$S35&""),0) -> 0 | AM35: =AK35+AL35 -> 0 | AN35: =IFERROR(GETPIVOTDATA("Row Labels",#REF!,"Dealer",""&$S$18&"","Model",""&$S35&""),0) -> 0 | AO35: =IFERROR(GETPIVOTDATA("RS Afi",#REF!,"Dealer",""&$S$18&"","Model",""&$S35&""),0) -> 0 | AP35: =IFERROR(GETPIVOTDATA("qty",#REF!,"Model",""&$S35&"","Dealer",""&$S$18&""),0) -> 0 | AQ35: =IFERROR(GETPIVOTDATA("volume_rs",#REF!,"Model",""&$S35&"","Dealer",""&$S$18&""),0) -> 0 | AR35: =AP35-AQ35 -> 0 | AS35: =IFERROR(GETPIVOTDATA("Area AGM",'Pvt OS'!#REF!,"Dealer",""&$S$18&"","Model",""&$S35&""),0) -> 0 | AT35: =AR35-AS35 -> 0
